Workbook

Sheet Plan Review Master List
A1: Reference Number | B1: Reference Name | C1: Reference Section | D1: Reference Date | E1: DCGS Plan | F1: Plan Section | G1: URL
A2: DODD 5000.01 | B2: =_xlfn.XLOOKUP(A2,'Reference Master List'!$A:$A,'Reference Master List'!$B:$B,"NOT FOUND") -> The Defense Acquisition System | C2: 1.2.a | D2: =_xlfn.XLOOKUP(A2,'Reference Master List'!$A:$A,'Reference Master List'!$D:$D,"NOT FOUND") -> 44770 | E2: LCSP | F2: 1 | G2: =_xlfn.XLOOKUP(A2,'Reference Master List'!$A:$A,'Reference Master List'!$E:$E,"NOT FOUND") -> https://www.esd.whs.mil/Portals/54/Documents/DD/issuances/dodd/500001p.pdf?ver=IxP_j399Em4zTd4PqFjuTQ%3d%3d
A3: DODD 5000.01 | B3: =_xlfn.XLOOKUP(A3,'Reference Master List'!$A:$A,'Reference Master List'!$B:$B,"NOT FOUND") -> The Defense Acquisition System | C3: 1.2.c | D3: =_xlfn.XLOOKUP(A3,'Reference Master List'!$A:$A,'Reference Master List'!$D:$D,"NOT FOUND") -> 44770 | E3: LCSP | F3: 1 | G3: =_xlfn.XLOOKUP(A3,'Reference Master List'!$A:$A,'Reference Master List'!$E:$E,"NOT FOUND") -> https://www.esd.whs.mil/Portals/54/Documents/DD/issuances/dodd/500001p.pdf?ver=IxP_j399Em4zTd4PqFjuTQ%3d%3d
A4: DODD 5000.01 | B4: =_xlfn.XLOOKUP(A4,'Reference Master List'!$A:$A,'Reference Master List'!$B:$B,"NOT FOUND") -> The Defense Acquisition System | C4: 1.2.v | D4: =_xlfn.XLOOKUP(A4,'Reference Master List'!$A:$A,'Reference Master List'!$D:$D,"NOT FOUND") -> 44770 | E4: LCSP | F4: 1 | G4: =_xlfn.XLOOKUP(A4,'Reference Master List'!$A:$A,'Reference Master List'!$E:$E,"NOT FOUND") -> https://www.esd.whs.mil/Portals/54/Documents/DD/issuances/dodd/500001p.pdf?ver=IxP_j399Em4zTd4PqFjuTQ%3d%3d
A5: DODI 5000.91 | B5: =_xlfn.XLOOKUP(A5,'Reference Master List'!$A:$A,'Reference Master List'!$B:$B,"NOT FOUND") -> Product Support Management for the Adaptive Acquisition Framework | C5: 4.1.c | D5: =_xlfn.XLOOKUP(A5,'Reference Master List'!$A:$A,'Reference Master List'!$D:$D,"NOT FOUND") -> 44504 | E5: LCSP | F5: 1 | G5: =_xlfn.XLOOKUP(A5,'Reference Master List'!$A:$A,'Reference Master List'!$E:$E,"NOT FOUND") -> https://www.esd.whs.mil/Portals/54/Documents/DD/issuances/dodi/500091p.PDF?ver=qk1slCU3Y0c1acIDocWyJA%3d%3d
A6: DODI 5000.91 | B6: =_xlfn.XLOOKUP(A6,'Reference Master List'!$A:$A,'Reference Master List'!$B:$B,"NOT FOUND") -> Product Support Management for the Adaptive Acquisition Framework | C6: 4.3.b | D6: =_xlfn.XLOOKUP(A6,'Reference Master List'!$A:$A,'Reference Master List'!$D:$D,"NOT FOUND") -> 44504 | E6: LCSP | F6: 1 | G6: =_xlfn.XLOOKUP(A6,'Reference Master List'!$A:$A,'Reference Master List'!$E:$E,"NOT FOUND") -> https://www.esd.whs.mil/Portals/54/Documents/DD/issuances/dodi/500091p.PDF?ver=qk1slCU3Y0c1acIDocWyJA%3d%3d
A7: DODI 5000.91 | B7: =_xlfn.XLOOKUP(A7,'Reference Master List'!$A:$A,'Reference Master List'!$B:$B,"NOT FOUND") -> Product Support Management for the Adaptive Acquisition Framework | C7: 4.3.c | D7: =_xlfn.XLOOKUP(A7,'Reference Master List'!$A:$A,'Reference Master List'!$D:$D,"NOT FOUND") -> 44504 | E7: LCSP | F7: 1 | G7: =_xlfn.XLOOKUP(A7,'Reference Master List'!$A:$A,'Reference Master List'!$E:$E,"NOT FOUND") -> https://www.esd.whs.mil/Portals/54/Documents/DD/issuances/dodi/500091p.PDF?ver=qk1slCU3Y0c1acIDocWyJA%3d%3d
A8: DODI 5000.91 | B8: =_xlfn.XLOOKUP(A8,'Reference Master List'!$A:$A,'Reference Master List'!$B:$B,"NOT FOUND") -> Product Support Management for the Adaptive Acquisition Framework | C8: 9.2.b | D8: =_xlfn.XLOOKUP(A8,'Reference Master List'!$A:$A,'Reference Master List'!$D:$D,"NOT FOUND") -> 44504 | E8: LCSP | F8: 1 | G8: =_xlfn.XLOOKUP(A8,'Reference Master List'!$A:$A,'Reference Master List'!$E:$E,"NOT FOUND") -> https://www.esd.whs.mil/Portals/54/Documents/DD/issuances/dodi/500091p.PDF?ver=qk1slCU3Y0c1acIDocWyJA%3d%3d
A9: DODD 5000.01 | B9: =_xlfn.XLOOKUP(A9,'Reference Master List'!$A:$A,'Reference Master List'!$B:$B,"NOT FOUND") -> The Defense Acquisition System | C9: 1.2.i | D9: =_xlfn.XLOOKUP(A9,'Reference Master List'!$A:$A,'Reference Master List'!$D:$D,"NOT FOUND") -> 44770 | E9: LCSP | F9: 2 | G9: =_xlfn.XLOOKUP(A9,'Reference Master List'!$A:$A,'Reference Master List'!$E:$E,"NOT FOUND") -> https://www.esd.whs.mil/Portals/54/Documents/DD/issuances/dodd/500001p.pdf?ver=IxP_j399Em4zTd4PqFjuTQ%3d%3d
A10: DODD 5000.01 | B10: =_xlfn.XLOOKUP(A10,'Reference Master List'!$A:$A,'Reference Master List'!$B:$B,"NOT FOUND") -> The Defense Acquisition System | C10: 1.2.l | D10: =_xlfn.XLOOKUP(A10,'Reference Master List'!$A:$A,'Reference Master List'!$D:$D,"NOT FOUND") -> 44770 | E10: LCSP | F10: 2 | G10: =_xlfn.XLOOKUP(A10,'Reference Master List'!$A:$A,'Reference Master List'!$E:$E,"NOT FOUND") -> https://www.esd.whs.mil/Portals/54/Documents/DD/issuances/dodd/500001p.pdf?ver=IxP_j399Em4zTd4PqFjuTQ%3d%3d
A11: DODD 5000.01 | B11: =_xlfn.XLOOKUP(A11,'Reference Master List'!$A:$A,'Reference Master List'!$B:$B,"NOT FOUND") -> The Defense Acquisition System | C11: 1.2.m | D11: =_xlfn.XLOOKUP(A11,'Reference Master List'!$A:$A,'Reference Master List'!$D:$D,"NOT FOUND") -> 44770 | E11: LCSP | F11: 2 | G11: =_xlfn.XLOOKUP(A11,'Reference Master List'!$A:$A,'Reference Master List'!$E:$E,"NOT FOUND") -> https://www.esd.whs.mil/Portals/54/Documents/DD/issuances/dodd/500001p.pdf?ver=IxP_j399Em4zTd4PqFjuTQ%3d%3d
A12: DODD 5000.01 | B12: =_xlfn.XLOOKUP(A12,'Reference Master List'!$A:$A,'Reference Master List'!$B:$B,"NOT FOUND") -> The Defense Acquisition System | C12: 1.2.w | D12: =_xlfn.XLOOKUP(A12,'Reference Master List'!$A:$A,'Reference Master List'!$D:$D,"NOT FOUND") -> 44770 | E12: LCSP | F12: 2 | G12: =_xlfn.XLOOKUP(A12,'Reference Master List'!$A:$A,'Reference Master List'!$E:$E,"NOT FOUND") -> https://www.esd.whs.mil/Portals/54/Documents/DD/issuances/dodd/500001p.pdf?ver=IxP_j399Em4zTd4PqFjuTQ%3d%3d
A13: DODI 5000.80 | B13: =_xlfn.XLOOKUP(A13,'Reference Master List'!$A:$A,'Reference Master List'!$B:$B,"NOT FOUND") -> Operation of the Middle Tier of Acquisition (MTA) | C13: 2.6.b | D13: =_xlfn.XLOOKUP(A13,'Reference Master List'!$A:$A,'Reference Master List'!$D:$D,"NOT FOUND") -> 45621 | E13: LCSP | F13: 2 | G13: =_xlfn.XLOOKUP(A13,'Reference Master List'!$A:$A,'Reference Master List'!$E:$E,"NOT FOUND") -> https://www.esd.whs.mil/Portals/54/Documents/DD/issuances/dodi/500080p.PDF?ver=QsDA5aJ20jnMMxhx1z5mJQ%3d%3d
... A30: DODI 5000.91 | B30: =_xlfn.XLOOKUP(A30,'Reference Master List'!$A:$A,'Reference Master List'!$B:$B,"NOT FOUND") -> Product Support Management for the Adaptive Acquisition Framework | C30: 8.2.c | D30: =_xlfn.XLOOKUP(A30,'Reference Master List'!$A:$A,'Reference Master List'!$D:$D,"NOT FOUND") -> 44504 | E30: LCSP | F30: 3.1 | G30: =_xlfn.XLOOKUP(A30,'Reference Master List'!$A:$A,'Reference Master List'!$E:$E,"NOT FOUND") -> https://www.esd.whs.mil/Portals/54/Documents/DD/issuances/dodi/500091p.PDF?ver=qk1slCU3Y0c1acIDocWyJA%3d%3d
A31: DODI 5000.91 | B31: =_xlfn.XLOOKUP(A31,'Reference Master List'!$A:$A,'Reference Master List'!$B:$B,"NOT FOUND") -> Product Support Management for the Adaptive Acquisition Framework | C31: 4.8 | D31: =_xlfn.XLOOKUP(A31,'Reference Master List'!$A:$A,'Reference Master List'!$D:$D,"NOT FOUND") -> 44504 | E31: LCSP | F31: 3.2 | G31: =_xlfn.XLOOKUP(A31,'Reference Master List'!$A:$A,'Reference Master List'!$E:$E,"NOT FOUND") -> https://www.esd.whs.mil/Portals/54/Documents/DD/issuances/dodi/500091p.PDF?ver=qk1slCU3Y0c1acIDocWyJA%3d%3d
A32: DODI 5000.91 | B32: =_xlfn.XLOOKUP(A32,'Reference Master List'!$A:$A,'Reference Master List'!$B:$B,"NOT FOUND") -> Product Support Management for the Adaptive Acquisition Framework | C32: 4.8.c | D32: =_xlfn.XLOOKUP(A32,'Reference Master List'!$A:$A,'Reference Master List'!$D:$D,"NOT FOUND") -> 44504 | E32: LCSP | F32: 3.2 | G32: =_xlfn.XLOOKUP(A32,'Reference Master List'!$A:$A,'Reference Master List'!$E:$E,"NOT FOUND") -> https://www.esd.whs.mil/Portals/54/Documents/DD/issuances/dodi/500091p.PDF?ver=qk1slCU3Y0c1acIDocWyJA%3d%3d
A33: DODI 5000.91 | B33: =_xlfn.XLOOKUP(A33,'Reference Master List'!$A:$A,'Reference Master List'!$B:$B,"NOT FOUND") -> Product Support Management for the Adaptive Acquisition Framework | C33: 6.2.c | D33: =_xlfn.XLOOKUP(A33,'Reference Master List'!$A:$A,'Reference Master List'!$D:$D,"NOT FOUND") -> 44504 | E33: LCSP | F33: 3.2 | G33: =_xlfn.XLOOKUP(A33,'Reference Master List'!$A:$A,'Reference Master List'!$E:$E,"NOT FOUND") -> https://www.esd.whs.mil/Portals/54/Documents/DD/issuances/dodi/500091p.PDF?ver=qk1slCU3Y0c1acIDocWyJA%3d%3d
A34: DODI 5000.91 | B34: =_xlfn.XLOOKUP(A34,'Reference Master List'!$A:$A,'Reference Master List'!$B:$B,"NOT FOUND") -> Product Support Management for the Adaptive Acquisition Framework | C34: 4.11.b | D34: =_xlfn.XLOOKUP(A34,'Reference Master List'!$A:$A,'Reference Master List'!$D:$D,"NOT FOUND") -> 44504 | E34: LCSP | F34: 3.2 | G34: =_xlfn.XLOOKUP(A34,'Reference Master List'!$A:$A,'Reference Master List'!$E:$E,"NOT FOUND") -> https://www.esd.whs.mil/Portals/54/Documents/DD/issuances/dodi/500091p.PDF?ver=qk1slCU3Y0c1acIDocWyJA%3d%3d
A35: DODI 5000.91 | B35: =_xlfn.XLOOKUP(A35,'Reference Master List'!$A:$A,'Reference Master List'!$B:$B,"NOT FOUND") -> Product Support Management for the Adaptive Acquisition Framework | C35: 4.8.a | D35: =_xlfn.XLOOKUP(A35,'Reference Master List'!$A:$A,'Reference Master List'!$D:$D,"NOT FOUND") -> 44504 | E35: LCSP | F35: 3.3 | G35: =_xlfn.XLOOKUP(A35,'Reference Master List'!$A:$A,'Reference Master List'!$E:$E,"NOT FOUND") -> https://www.esd.whs.mil/Portals/54/Documents/DD/issuances/dodi/500091p.PDF?ver=qk1slCU3Y0c1acIDocWyJA%3d%3d
A36: DODI 5000.91 | B36: =_xlfn.XLOOKUP(A36,'Reference Master List'!$A:$A,'Reference Master List'!$B:$B,"NOT FOUND") -> Product Support Management for the Adaptive Acquisition Framework | C36: 4.8.a | D36: =_xlfn.XLOOKUP(A36,'Reference Master List'!$A:$A,'Reference Master List'!$D:$D,"NOT FOUND") -> 44504 | E36: LCSP | F36: 3.3 | G36: =_xlfn.XLOOKUP(A36,'Reference Master List'!$A:$A,'Reference Master List'!$E:$E,"NOT FOUND") -> https://www.esd.whs.mil/Portals/54/Documents/DD/issuances/dodi/500091p.PDF?ver=qk1slCU3Y0c1acIDocWyJA%3d%3d
A37: DODI 5000.91 | B37: =_xlfn.XLOOKUP(A37,'Reference Master List'!$A:$A,'Reference Master List'!$B:$B,"NOT FOUND") -> Product Support Management for the Adaptive Acquisition Framework | C37: 7.2.b | D37: =_xlfn.XLOOKUP(A37,'Reference Master List'!$A:$A,'Reference Master List'!$D:$D,"NOT FOUND") -> 44504 | E37: LCSP | F37: 3.3 | G37: =_xlfn.XLOOKUP(A37,'Reference Master List'!$A:$A,'Reference Master List'!$E:$E,"NOT FOUND") -> https://www.esd.whs.mil/Portals/54/Documents/DD/issuances/dodi/500091p.PDF?ver=qk1slCU3Y0c1acIDocWyJA%3d%3d
A38: DODI 5000.91 | B38: =_xlfn.XLOOKUP(A38,'Reference Master List'!$A:$A,'Reference Master List'!$B:$B,"NOT FOUND") -> Product Support Management for the Adaptive Acquisition Framework | C38: 4.7.b | D38: =_xlfn.XLOOKUP(A38,'Reference Master List'!$A:$A,'Reference Master List'!$D:$D,"NOT FOUND") -> 44504 | E38: LCSP | F38: 3.3 | G38: =_xlfn.XLOOKUP(A38,'Reference Master List'!$A:$A,'Reference Master List'!$E:$E,"NOT FOUND") -> https://www.esd.whs.mil/Portals/54/Documents/DD/issuances/dodi/500091p.PDF?ver=qk1slCU3Y0c1acIDocWyJA%3d%3d
A39: DODI 5000.80 | B39: =_xlfn.XLOOKUP(A39,'Reference Master List'!$A:$A,'Reference Master List'!$B:$B,"NOT FOUND") -> Operation of the Middle Tier of Acquisition (MTA) | C39: 2.6.b | D39: =_xlfn.XLOOKUP(A39,'Reference Master List'!$A:$A,'Reference Master List'!$D:$D,"NOT FOUND") -> 45621 | E39: LCSP | F39: 4 | G39: =_xlfn.XLOOKUP(A39,'Reference Master List'!$A:$A,'Reference Master List'!$E:$E,"NOT FOUND") -> https://www.esd.whs.mil/Portals/54/Documents/DD/issuances/dodi/500080p.PDF?ver=QsDA5aJ20jnMMxhx1z5mJQ%3d%3d
A40: DODI 5000.88 | B40: =_xlfn.XLOOKUP(A40,'Reference Master List'!$A:$A,'Reference Master List'!$B:$B,"NOT FOUND") -> Engineering of Defense Systems | C40: 3.6.f | D40: =_xlfn.XLOOKUP(A40,'Reference Master List'!$A:$A,'Reference Master List'!$D:$D,"NOT FOUND") -> 44153 | E40: LCSP | F40: 4.1 | G40: =_xlfn.XLOOKUP(A40,'Reference Master List'!$A:$A,'Reference Master List'!$E:$E,"NOT FOUND") -> https://www.esd.whs.mil/Portals/54/Documents/DD/issuances/dodi/500088p.PDF?ver=O8LFc8NzlyJX-SgM2Haalw%3d%3d
A41: DODI 4140.01 | B41: =_xlfn.XLOOKUP(A41,'Reference Master List'!$A:$A,'Reference Master List'!$B:$B,"NOT FOUND") -> DoD Supply Chain Materiel Management Policy | C41: 3.7.a | D41: =_xlfn.XLOOKUP(A41,'Reference Master List'!$A:$A,'Reference Master List'!$D:$D,"NOT FOUND") -> 43530 | E41: LCSP | F41: 4.2 | G41: =_xlfn.XLOOKUP(A41,'Reference Master List'!$A:$A,'Reference Master List'!$E:$E,"NOT FOUND") -> https://www.esd.whs.mil/Portals/54/Documents/DD/issuances/dodi/414001p.PDF?ver=x3uRuJnmOdRqFqi2XkEYrQ%3d%3d
A42: DODI 5000.67 | B42: =_xlfn.XLOOKUP(A42,'Reference Master List'!$A:$A,'Reference Master List'!$B:$B,"NOT FOUND") -> Prevention and Mitigation of Corrosion on DoD Military Equipment and Infrastructure | C42: 4.a | D42: =_xlfn.XLOOKUP(A42,'Reference Master List'!$A:$A,'Reference Master List'!$D:$D,"NOT FOUND") -> 43343 | E42: LCSP | F42: 4.2 | G42: =_xlfn.XLOOKUP(A42,'Reference Master List'!$A:$A,'Reference Master List'!$E:$E,"NOT FOUND") -> https://www.esd.whs.mil/Portals/54/Documents/DD/issuances/dodi/500067p.pdf?ver=2019-03-07-133844-480
A43: DODI 5000.67 | B43: =_xlfn.XLOOKUP(A43,'Reference Master List'!$A:$A,'Reference Master List'!$B:$B,"NOT FOUND") -> Prevention and Mitigation of Corrosion on DoD Military Equipment and Infrastructure | C43: 4.b | D43: =_xlfn.XLOOKUP(A43,'Reference Master List'!$A:$A,'Reference Master List'!$D:$D,"NOT FOUND") -> 43343 | E43: LCSP | F43: 4.2 | G43: =_xlfn.XLOOKUP(A43,'Reference Master List'!$A:$A,'Reference Master List'!$E:$E,"NOT FOUND") -> https://www.esd.whs.mil/Portals/54/Documents/DD/issuances/dodi/500067p.pdf?ver=2019-03-07-133844-480
... A48: DODI 5000.88 | B48: =_xlfn.XLOOKUP(A48,'Reference Master List'!$A:$A,'Reference Master List'!$B:$B,"NOT FOUND") -> Engineering of Defense Systems | C48: 3.7.a | D48: =_xlfn.XLOOKUP(A48,'Reference Master List'!$A:$A,'Reference Master List'!$D:$D,"NOT FOUND") -> 44153 | E48: LCSP | F48: 4.4 | G48: =_xlfn.XLOOKUP(A48,'Reference Master List'!$A:$A,'Reference Master List'!$E:$E,"NOT FOUND") -> https://www.esd.whs.mil/Portals/54/Documents/DD/issuances/dodi/500088p.PDF?ver=O8LFc8NzlyJX-SgM2Haalw%3d%3d
A49: DODI 5000.91 | B49: =_xlfn.XLOOKUP(A49,'Reference Master List'!$A:$A,'Reference Master List'!$B:$B,"NOT FOUND") -> Product Support Management for the Adaptive Acquisition Framework | C49: 4.4 | D49: =_xlfn.XLOOKUP(A49,'Reference Master List'!$A:$A,'Reference Master List'!$D:$D,"NOT FOUND") -> 44504 | E49: LCSP | F49: 4.4.1 | G49: =_xlfn.XLOOKUP(A49,'Reference Master List'!$A:$A,'Reference Master List'!$E:$E,"NOT FOUND") -> https://www.esd.whs.mil/Portals/54/Documents/DD/issuances/dodi/500091p.PDF?ver=qk1slCU3Y0c1acIDocWyJA%3d%3d
A50: DODI 5000.91 | B50: =_xlfn.XLOOKUP(A50,'Reference Master List'!$A:$A,'Reference Master List'!$B:$B,"NOT FOUND") -> Product Support Management for the Adaptive Acquisition Framework | C50: 4.4 | D50: =_xlfn.XLOOKUP(A50,'Reference Master List'!$A:$A,'Reference Master List'!$D:$D,"NOT FOUND") -> 44504 | E50: LCSP | F50: 4.4.1.1 | G50: =_xlfn.XLOOKUP(A50,'Reference Master List'!$A:$A,'Reference Master List'!$E:$E,"NOT FOUND") -> https://www.esd.whs.mil/Portals/54/Documents/DD/issuances/dodi/500091p.PDF?ver=qk1slCU3Y0c1acIDocWyJA%3d%3d
A51: DODI 5000.91 | B51: =_xlfn.XLOOKUP(A51,'Reference Master List'!$A:$A,'Reference Master List'!$B:$B,"NOT FOUND") -> Product Support Management for the Adaptive Acquisition Framework | C51: 4.5.c | D51: =_xlfn.XLOOKUP(A51,'Reference Master List'!$A:$A,'Reference Master List'!$D:$D,"NOT FOUND") -> 44504 | E51: LCSP | F51: 4.4.1.1 | G51: =_xlfn.XLOOKUP(A51,'Reference Master List'!$A:$A,'Reference Master List'!$E:$E,"NOT FOUND") -> https://www.esd.whs.mil/Portals/54/Documents/DD/issuances/dodi/500091p.PDF?ver=qk1slCU3Y0c1acIDocWyJA%3d%3d
A52: DODI 5000.88 | B52: =_xlfn.XLOOKUP(A52,'Reference Master List'!$A:$A,'Reference Master List'!$B:$B,"NOT FOUND") -> Engineering of Defense Systems | C52: 3.3.g | D52: =_xlfn.XLOOKUP(A52,'Reference Master List'!$A:$A,'Reference Master List'!$D:$D,"NOT FOUND") -> 44153 | E52: LCSP | F52: 4.4.2 | G52: =_xlfn.XLOOKUP(A52,'Reference Master List'!$A:$A,'Reference Master List'!$E:$E,"NOT FOUND") -> https://www.esd.whs.mil/Portals/54/Documents/DD/issuances/dodi/500088p.PDF?ver=O8LFc8NzlyJX-SgM2Haalw%3d%3d
A53: DODD 5000.01 | B53: =_xlfn.XLOOKUP(A53,'Reference Master List'!$A:$A,'Reference Master List'!$B:$B,"NOT FOUND") -> The Defense Acquisition System | C53: 1.2.k | D53: =_xlfn.XLOOKUP(A53,'Reference Master List'!$A:$A,'Reference Master List'!$D:$D,"NOT FOUND") -> 44770 | E53: LCSP | F53: 4.4.3 | G53: =_xlfn.XLOOKUP(A53,'Reference Master List'!$A:$A,'Reference Master List'!$E:$E,"NOT FOUND") -> https://www.esd.whs.mil/Portals/54/Documents/DD/issuances/dodd/500001p.pdf?ver=IxP_j399Em4zTd4PqFjuTQ%3d%3d
A54: DODI 5000.91 | B54: =_xlfn.XLOOKUP(A54,'Reference Master List'!$A:$A,'Reference Master List'!$B:$B,"NOT FOUND") -> Product Support Management for the Adaptive Acquisition Framework | C54: 4.2 | D54: =_xlfn.XLOOKUP(A54,'Reference Master List'!$A:$A,'Reference Master List'!$D:$D,"NOT FOUND") -> 44504 | E54: LCSP | F54: 4.4.3 | G54: =_xlfn.XLOOKUP(A54,'Reference Master List'!$A:$A,'Reference Master List'!$E:$E,"NOT FOUND") -> https://www.esd.whs.mil/Portals/54/Documents/DD/issuances/dodi/500091p.PDF?ver=qk1slCU3Y0c1acIDocWyJA%3d%3d
A55: DODI 5000.91 | B55: =_xlfn.XLOOKUP(A55,'Reference Master List'!$A:$A,'Reference Master List'!$B:$B,"NOT FOUND") -> Product Support Management for the Adaptive Acquisition Framework | C55: 4.11.e | D55: =_xlfn.XLOOKUP(A55,'Reference Master List'!$A:$A,'Reference Master List'!$D:$D,"NOT FOUND") -> 44504 | E55: LCSP | F55: 4.4.3 | G55: =_xlfn.XLOOKUP(A55,'Reference Master List'!$A:$A,'Reference Master List'!$E:$E,"NOT FOUND") -> https://www.esd.whs.mil/Portals/54/Documents/DD/issuances/dodi/500091p.PDF?ver=qk1slCU3Y0c1acIDocWyJA%3d%3d
A56: DODI 5000.88 | B56: =_xlfn.XLOOKUP(A56,'Reference Master List'!$A:$A,'Reference Master List'!$B:$B,"NOT FOUND") -> Engineering of Defense Systems | C56: 3.4.b | D56: =_xlfn.XLOOKUP(A56,'Reference Master List'!$A:$A,'Reference Master List'!$D:$D,"NOT FOUND") -> 44153 | E56: LCSP | F56: 4.5 | G56: =_xlfn.XLOOKUP(A56,'Reference Master List'!$A:$A,'Reference Master List'!$E:$E,"NOT FOUND") -> https://www.esd.whs.mil/Portals/54/Documents/DD/issuances/dodi/500088p.PDF?ver=O8LFc8NzlyJX-SgM2Haalw%3d%3d
A57: DODI 5000.88 | B57: =_xlfn.XLOOKUP(A57,'Reference Master List'!$A:$A,'Reference Master List'!$B:$B,"NOT FOUND") -> Engineering of Defense Systems | C57: 3.4.c | D57: =_xlfn.XLOOKUP(A57,'Reference Master List'!$A:$A,'Reference Master List'!$D:$D,"NOT FOUND") -> 44153 | E57: LCSP | F57: 4.5 | G57: =_xlfn.XLOOKUP(A57,'Reference Master List'!$A:$A,'Reference Master List'!$E:$E,"NOT FOUND") -> https://www.esd.whs.mil/Portals/54/Documents/DD/issuances/dodi/500088p.PDF?ver=O8LFc8NzlyJX-SgM2Haalw%3d%3d
A58: DODI 5000.82 | B58: =_xlfn.XLOOKUP(A58,'Reference Master List'!$A:$A,'Reference Master List'!$B:$B,"NOT FOUND") -> Requirements for the Acquisition of Digital Capabilities | C58: 3.9.a | D58: =_xlfn.XLOOKUP(A58,'Reference Master List'!$A:$A,'Reference Master List'!$D:$D,"NOT FOUND") -> 45078 | E58: LCSP | F58: 4.5 | G58: =_xlfn.XLOOKUP(A58,'Reference Master List'!$A:$A,'Reference Master List'!$E:$E,"NOT FOUND") -> https://www.esd.whs.mil/Portals/54/Documents/DD/issuances/dodi/500082p.pdf?ver=QZaqmiSGQ9iDARW1j-_hgw%3d%3d
A59: DODI 5000.82 | B59: =_xlfn.XLOOKUP(A59,'Reference Master List'!$A:$A,'Reference Master List'!$B:$B,"NOT FOUND") -> Requirements for the Acquisition of Digital Capabilities | C59: 3.9.g | D59: =_xlfn.XLOOKUP(A59,'Reference Master List'!$A:$A,'Reference Master List'!$D:$D,"NOT FOUND") -> 45078 | E59: LCSP | F59: 4.5 | G59: =_xlfn.XLOOKUP(A59,'Reference Master List'!$A:$A,'Reference Master List'!$E:$E,"NOT FOUND") -> https://www.esd.whs.mil/Portals/54/Documents/DD/issuances/dodi/500082p.pdf?ver=QZaqmiSGQ9iDARW1j-_hgw%3d%3d
A60: DODI 5015.02 | B60: =_xlfn.XLOOKUP(A60,'Reference Master List'!$A:$A,'Reference Master List'!$B:$B,"NOT FOUND") -> DoW Records Management Program | C60: 3.d | D60: =_xlfn.XLOOKUP(A60,'Reference Master List'!$A:$A,'Reference Master List'!$D:$D,"NOT FOUND") -> 46199 | E60: LCSP | F60: 4.5 | G60: =_xlfn.XLOOKUP(A60,'Reference Master List'!$A:$A,'Reference Master List'!$E:$E,"NOT FOUND") -> https://www.esd.whs.mil/Portals/54/Documents/DD/issuances/dodi/501502p.PDF?ver=OJUzNkxKuwZEaJjTAm7uTQ%3d%3d
...

Sheet Reference Master List
A1: Reference Number | B1: Reference Name | C1: Status | D1: Reference Date | E1: URL
A2: DODD 3000.09 | B2: Autonmy in Weapon Systems | D2: 44951 | E2: https://www.esd.whs.mil/Portals/54/Documents/DD/issuances/DODd/300009p.PDF
A3: DODD 4715.0E | B3: Environment, Safety, and Occupational Health (ESOH) | D3: 43829 | E3: https://www.esd.whs.mil/Portals/54/Documents/DD/issuances/dodd/47151Ep.PDF?ver=2019-12-30-141505-590
A4: DODD 5000.01 | B4: The Defense Acquisition System | D4: 44770 | E4: https://www.esd.whs.mil/Portals/54/Documents/DD/issuances/dodd/500001p.pdf?ver=IxP_j399Em4zTd4PqFjuTQ%3d%3d
A5: DODD 5250.01 | B5: Management of Intelligence Mission Data (IMD) in DOD Acquisition | D5: 42976 | E5: https://www.esd.whs.mil/Portals/54/Documents/DD/issuances/dodd/525001p.pdf?ver=2019-07-08-094552-877
A6: DODM 5000.96 | B6: Operational and Live Fire Test and Evaluation of Software | C6: Canceled 2026-08-03 | D6: 45635 | E6: https://www.esd.whs.mil/Portals/54/Documents/DD/issuances/DODm/500096p.PDF?ver=Wxw2Clk4AzUi5xtKSEpt8A%3d%3d
A7: DODM 5000.99 | B7: Realistic Full Spectrum Survivability and Lethality Testing | C7: Canceled 2026-08-03 | D7: 45635 | E7: https://www.esd.whs.mil/Portals/54/Documents/DD/issuances/DODm/500099p.PDF?ver=N-6QYZbYutUS3r9xyRoJVg%3d%3d
A8: DODM 5000.100 | B8: Test and Evaluation Master Plans and Test and Evaluation Strategies | C8: Canceled 2026-08-03 | D8: 45635 | E8: https://www.esd.whs.mil/Portals/54/Documents/DD/issuances/DODm/5000100m.PDF?ver=ljPHJcRJzTogh9jxrHh9IA%3d%3d
A9: DODM 5000.101 | B9: Operational Test and Evaluation and Live Fire Test and Evaluation of Artificial Intelligence-Enabled and Autonomous Systems | C9: Canceled 2026-08-03 | D9: 45635 | E9: https://www.esd.whs.mil/Portals/54/Documents/DD/issuances/DODm/5000101p.PDF?ver=FfOR56lIK5S1LDFfSlYwYQ%3d%3d
A10: DODM 5000.102 | B10: Modeling and Simulation Verification, Validation and Accreditation For Operational Test and Evaluation and Live Fire Test and Evaluation | C10: Canceled 2026-08-03 | D10: 45635 | E10: https://www.esd.whs.mil/Portals/54/Documents/DD/issuances/DODm/5000102m.PDF?ver=9JF3bqGJFcGiF3J3KgSTNg%3d%3d
A11: DODI 1650.01 | B11: XXX | C11: Not A Valid Document | D11: XXX | E11: XXX
A12: DODI 4120.24 | B12: Defense Standardization Program | D12: 44651 | E12: https://www.esd.whs.mil/Portals/54/Documents/DD/issuances/dodi/412024p.pdf?ver=AXPUKcdZnh18wAAfx63Vnw%3d%3d
A13: DODI 4140.01 | B13: DoD Supply Chain Materiel Management Policy | D13: 43530 | E13: https://www.esd.whs.mil/Portals/54/Documents/DD/issuances/dodi/414001p.PDF?ver=x3uRuJnmOdRqFqi2XkEYrQ%3d%3d
A14: DODI 4630.09 | B14: Communications Waveform Management and Standardization | D14: 44158 | E14: https://www.esd.whs.mil/Portals/54/Documents/DD/issuances/dodi/463009p.pdf?ver=_AodYK2mcqGmezDUQiIGhA%3d%3d
A15: DODI 4650.01 | B15: Policy and Procedures for Management and Use of the Electromagnetic Spectrum | D15: 43025 | E15: https://www.esd.whs.mil/Portals/54/Documents/DD/issuances/dodi/465001p.pdf?ver=2019-01-24-112300-743
A16: DODI 5000.02 | B16: Operation of the Adaptive Acquisition Framework | D16: 43853 | E16: https://www.esd.whs.mil/Portals/54/Documents/DD/issuances/dodi/500002p.PDF?ver=dwMrujJ8qEhU9oageF1fTA%3d%3d
A17: DODI 5000.61 | B17: DoD Modeling and Simulation Verification, Validation, and Accreditation | D17: 45552 | E17: https://www.esd.whs.mil/Portals/54/Documents/DD/issuances/dodi/500061p.pdf?ver=jRGu271k46n5T9NPRwT-sQ%3d%3d
A18: DODI 5000.67 | B18: Prevention and Mitigation of Corrosion on DoD Military Equipment and Infrastructure | D18: 43343 | E18: https://www.esd.whs.mil/Portals/54/Documents/DD/issuances/dodi/500067p.pdf?ver=2019-03-07-133844-480
A19: DODI 5000.73 | B19: Cost Analysis Guidance and Procedures | D19: 45589 | E19: https://www.esd.whs.mil/Portals/54/Documents/DD/issuances/dodi/500073p.pdf?ver=Mekug5erzBO86eUqBSaeaw%3d%3d
A20: DODI 5000.74 | B20: Defense Acquisition of Services | D20: 44371 | E20: https://www.esd.whs.mil/Portals/54/Documents/DD/issuances/dodi/500074p.pdf?ver=IZVR50IvjWDdP81SFWQh5Q%3d%3d
A21: DODI 5000.80 | B21: Operation of the Middle Tier of Acquisition (MTA) | D21: 45621 | E21: https://www.esd.whs.mil/Portals/54/Documents/DD/issuances/dodi/500080p.PDF?ver=QsDA5aJ20jnMMxhx1z5mJQ%3d%3d
A22: DODI 5000.81 | B22: Urgent Capability Acquisition | D22: 43830 | E22: https://www.esd.whs.mil/Portals/54/Documents/DD/issuances/dodi/500081p.PDF?ver=2019-12-31-133941-660
A23: DODI 5000.82 | B23: Requirements for the Acquisition of Digital Capabilities | D23: 45078 | E23: https://www.esd.whs.mil/Portals/54/Documents/DD/issuances/dodi/500082p.pdf?ver=QZaqmiSGQ9iDARW1j-_hgw%3d%3d
... A31: DODI 5000.95 | B31: Human Systems Integration in Defense Acquisition | D31: 44652 | E31: https://www.esd.whs.mil/Portals/54/Documents/DD/issuances/dodi/500095p.PDF?ver=C1L4ZM9Wi4Qa4p7JP7EPtA%3d%3d
A32: DODI 5000.98 | B32: Operational Test and Evaluation and Live Fire Test and Evaluation of Artificial Intelligence-Enabled and Autonomous Systems | C32: Canceled 2026-08-03 | D32: 45635 | E32: https://www.esd.whs.mil/Portals/54/Documents/DD/issuances/dodi/500098p.PDF?ver=InJ_BDOOVcUHyurlNv_FAg%3d%3d
A33: DODI 5015.02 | B33: DoW Records Management Program | D33: 46199 | E33: https://www.esd.whs.mil/Portals/54/Documents/DD/issuances/dodi/501502p.PDF?ver=OJUzNkxKuwZEaJjTAm7uTQ%3d%3d
A34: DODI 5200.44 | B34: Protection of Mission Critical Functions to Achieve Trusted Systems and Networks | D34: 45338 | E34: https://www.esd.whs.mil/Portals/54/Documents/DD/issuances/dodi/520044p.pdf?ver=FykYguJCo0S8RyRGdriRvg%3d%3d
A35: DODI 8330.01 | B35: Interoperability of Information Technology, Including National Security Systems | D35: 44831 | E35: https://www.esd.whs.mil/Portals/54/Documents/DD/issuances/dodi/833001p.pdf?ver=c7Bds_aCFKSe7SK_MiYBIg%3d%3d
A36: DODI 8440.01 | B36: DoD Information Technology (IT) Service Management (ITSM) | D36: 42362 | E36: https://www.esd.whs.mil/Portals/54/Documents/DD/issuances/dodi/844001p.pdf
A37: DODI 8500.01 | B37: Cybersecurity | D37: 43745 | E37: https://www.esd.whs.mil/Portals/54/Documents/DD/issuances/dodi/850001_2014.pdf?ver=2019-10-07-112048-860
A38: DODI 8510.01 | B38: Risk Management Framework for DoD Systems | D38: 44761 | E38: https://www.esd.whs.mil/Portals/54/Documents/DD/issuances/dodi/851001p.pdf?ver=5YnACrAlUCPZ_qeq4T5nlg%3d%3d
A39: MIL-HDBK-61B | B39: Configuration Management Guidance | D39: 45884 | E39: https://quicksearch.dla.mil/Transient/4D9CE4ACB1B74FFC874DE57D349F3740.pdf
A40: MIL-HDBK-189C | B40: Reliability Growth Management | D40: 42447 | E40: https://quicksearch.dla.mil/Transient/62299454E1FF4E6082B94955AE748F38.pdf
A41: MIL-HDBK-727 | B41: Design Guidance for Producibility | C41: Canceled 2026-06-29 | D41: 45883 | E41: https://quicksearch.dla.mil/Transient/8B1764D69FB948A3A3A60DAAF23A5467.pdf
A42: MIL-STD-882E | B42: System Safety | D42: 45196 | E42: https://quicksearch.dla.mil/Transient/4A466D8B3FA0466A942877E15486DEB6.pdf
A43: DAFI 14-411 | B43: Acquisition Intelligence | D43: 45707 | E43: https://static.e-publishing.af.mil/production/1/af_a2_6/publication/dafi14-411/dafi14-411.pdf
A44: DAFI 99-103 | B44: Test and Evaluation | D44: 46168 | E44: https://static.e-publishing.af.mil/production/1/af_te/publication/dodi5000.89_dafi99-103/dodi5000.89_dafi99-103.pdf
A45: DAFI 63-150 | B45: Operation of the Software Acquisition Pathway | D45: 44450 | E45: https://static.e-publishing.af.mil/production/1/saf_aq/publication/dodi5000.87_dafi63-150/dodi5000.87_afi63-150.pdf
A46: DAFI 63-151 | B46: Major Capability Acquisition | D46: 44792 | E46: https://static.e-publishing.af.mil/production/1/saf_aq/publication/dodi5000.85_dafi63-151/dodi5000.85_dafi63-151.pdf
A47: DAFI 63-101/20-101 | B47: Integrated Life Cycle Management | D47: 45953 | E47: https://static.e-publishing.af.mil/production/1/saf_aq/publication/dafi63-101_20-101/dafi63-101_20-101.pdf
...
